<mujoco model="sawyer_no_base">
    <compiler angle="radian" />
    <size njmax="500" nconmax="100" />
    <asset>
        <mesh name="base" file="sawyer_description/meshes/sawyer_pv/base.stl" />
        <mesh name="l0" file="sawyer_description/meshes/sawyer_mp3/l0.stl" />
        <mesh name="l1" file="sawyer_description/meshes/sawyer_mp3/l1.stl" />
        <mesh name="l2" file="sawyer_description/meshes/sawyer_pv/l2.stl" />
        <mesh name="l3" file="sawyer_description/meshes/sawyer_pv/l3.stl" />
        <mesh name="l4" file="sawyer_description/meshes/sawyer_pv/l4.stl" />
        <mesh name="l5" file="sawyer_description/meshes/sawyer_pv/l5.STL" />
        <mesh name="l6" file="sawyer_description/meshes/sawyer_mp1/l6.STL" />
        <mesh name="electric_gripper_base" file="rethink_ee_description/meshes/electric_gripper/electric_gripper_base.STL" />
        <mesh name="standard_narrow" file="rethink_ee_description/meshes/electric_gripper/fingers/standard_narrow.STL" />
        <mesh name="half_round_tip" file="rethink_ee_description/meshes/electric_gripper/fingers/half_round_tip.STL" />
    </asset>
    <worldbody>
        <body name="right_arm_base_link" pos="0 0 0">
            <inertial pos="-0.0006241 -2.8025e-05 0.065404" quat="-0.209285 0.674441 0.227335 0.670558" mass="2.0687" diaginertia="0.00740351 0.00681776 0.00672942" />
            <geom type="mesh" contype="0" conaffinity="0" group="1" rgba="0.5 0.1 0.1 1" mesh="base" />
            <geom size="0.08 0.12" pos="0 0 0.12" type="cylinder" rgba="0.5 0.1 0.1 1" />
            <body name="right_l0" pos="0 0 0.08">
                <inertial pos="0.024366 0.010969 0.14363" quat="0.894823 0.00899958 -0.170275 0.412573" mass="5.3213" diaginertia="0.0651588 0.0510944 0.0186218" />
                <joint name="right_j0" pos="0 0 0" axis="0 0 1" limited="true" range="-3.0503 3.0503" />
                <geom type="mesh" contype="0" conaffinity="0" group="1" rgba="0.5 0.1 0.1 1" mesh="l0" />
                <geom size="0.07" pos="0.081 0 0.237" rgba="0.5 0.1 0.1 1" />
                <body name="right_l1" pos="0.081 0.05 0.237" quat="0.5 -0.5 0.5 0.5">
                    <inertial pos="-0.0030849 -0.026811 0.092521" quat="0.424888 0.891987 0.132364 -0.0794296" mass="4.505" diaginertia="0.0224339 0.0221624 0.0097097" />
                    <joint name="right_j1" pos="0 0 0" axis="0 0 1" limited="true" range="-3.8183 2.2824" />
                    <geom type="mesh" contype="0" conaffinity="0" group="1" rgba="0.5 0.1 0.1 1" mesh="l1" />
                    <geom size="0.07" pos="0 0 0.1225" rgba="0.5 0.1 0.1 1" />
                    <body name="right_l2" pos="0 -0.14 0.1425" quat="0.707107 0.707107 0 0">
                        <inertial pos="-0.00016232 -0.015346 0.13445" quat="0.707249 -0.0541564 0.0533441 0.702866" mass="1.7251" diaginertia="0.0255023 0.025176 0.00285946" />
                        <joint name="right_j2" pos="0 0 0" axis="0 0 1" limited="true" range="-3.0514 3.0514" />
                        <geom type="mesh" contype="0" conaffinity="0" group="1" rgba="0.5 0.1 0.1 1" mesh="l2" />
                        <geom size="0.06 0.175" pos="0 0 0.14" type="cylinder" rgba="0.5 0.1 0.1 1" />
                        <body name="right_l3" pos="0 -0.042 0.26" quat="0.707107 -0.707107 0 0">
                            <inertial pos="-0.0046678 -0.028394 -0.083127" quat="0.894367 0.380888 -0.106513 0.209016" mass="2.4743" diaginertia="0.0100572 0.00959393 0.00350313" />
                            <joint name="right_j3" pos="0 0 0" axis="0 0 1" limited="true" range="-3.0514 3.0514" />
                            <geom type="mesh" contype="0" conaffinity="0" group="1" rgba="0.5 0.1 0.1 1" mesh="l3" />
                            <geom size="0.06" pos="0 -0.01 -0.12" rgba="0.5 0.1 0.1 1" />
                            <body name="right_l4" pos="0 -0.125 -0.1265" quat="0.707107 0.707107 0 0">
                                <inertial pos="-0.0027794 0.0076558 0.13273" quat="0.801274 0.0333339 -0.0340185 0.596399" mass="1.0433" diaginertia="0.013057 0.0129029 0.00113257" />
                                <joint name="right_j4" pos="0 0 0" axis="0 0 1" limited="true" range="-2.9842 2.9842" />
                                <geom type="mesh" contype="0" conaffinity="0" group="1" rgba="0.5 0.1 0.1 1" mesh="l4" />
                                <geom size="0.045 0.18" pos="0 0 0.14" type="cylinder" rgba="0.5 0.1 0.1 1" />
                                <body name="right_l5" pos="0 0.031 0.275" quat="0.707107 -0.707107 0 0">
                                    <inertial pos="0.0062067 -0.024291 0.075564" quat="0.405457 0.912624 0.0521713 0.000995062" mass="1.5343" diaginertia="0.00461663 0.0041769 0.00178717" />
                                    <joint name="right_j5" pos="0 0 0" axis="0 0 1" limited="true" range="-2.9842 2.9842" />
                                    <geom type="mesh" contype="0" conaffinity="0" group="1" rgba="0.5 0.1 0.1 1" mesh="l5" />
                                    <geom size="0.06" pos="0.01 0 0.09" rgba="0.5 0.1 0.1 1" />
                                    <body name="right_l6" pos="0 -0.11 0.1053" quat="0.0616248 0.06163 -0.704416 0.704416">
                                        <inertial pos="-8.0726e-06 0.0085838 -0.0049566" quat="0.479044 0.515636 -0.513069 0.491322" mass="0.3292" diaginertia="0.000360258 0.000311068 0.000214974" />
                                        <joint name="right_j6" pos="0 0 0" axis="0 0 1" limited="true" range="-4.7104 4.7104" />
                                        <geom type="mesh" contype="0" conaffinity="0" group="1" rgba="0.5 0.1 0.1 1" mesh="l6" />
                                        <geom size="0.065 0.025" pos="0 0 -0.005" type="cylinder" rgba="0.5 0.1 0.1 1" />
                                        <body name="right_hand" pos="0 0 0.0245" quat="0.707105 0 0 0.707108">
                                            <inertial pos="1e-08 1e-08 1e-08" quat="0.820473 0.339851 -0.17592 0.424708" mass="1e-08" diaginertia="1e-08 1e-08 1e-08" />
                                            <geom size="1e-08 5e-09" type="cylinder" />
                                            <body name="right_gripper_base" pos="0 0 0.025">
                                                <inertial pos="0 0 0" quat="-0.5 0.5 0.5 0.5" mass="0.3" diaginertia="3e-08 2e-08 2e-08" />
                                                <geom quat="0 0 0.707107 0.707107" type="mesh" contype="0" conaffinity="0" group="1" mesh="electric_gripper_base" />
                                                <geom size="0.029 0.05" quat="0 0 0.707107 0.707107" type="cylinder" />
                                                <body name="right_gripper" pos="0 0 0.095">
                                                    <inertial pos="0 0 0" mass="0.0001" diaginertia="0 0 0" />
                                                </body>
                                                <body name="r_gripper_l_finger" pos="0 -0.0015 0.02">
                                                    <inertial pos="0 0 0" quat="0 0 0 -1" mass="0.02" diaginertia="0.01 0.01 0.01" />
                                                    <joint name="r_gripper_l_finger_joint" pos="0 0 0" axis="0 1 0" type="slide" limited="true" range="0 0.020833" />
                                                    <geom quat="0 0 0 -1" type="mesh" contype="0" conaffinity="0" group="1" mesh="standard_narrow" />
                                                    <geom size="0.005 0.00675 0.0375" pos="0 0.01725 0.04" quat="0 0 0 -1" type="box" />
                                                    <geom size="0.005 0.025 0.0085" pos="-0.005 -0.003 0.0083" quat="0 0 0 -1" type="box" />
                                                    <body name="r_gripper_l_finger_tip" pos="0 0.01725 0.075">
                                                        <inertial pos="0 0 0" quat="0 0 0 1" mass="0.01" diaginertia="0.01 0.01 0.01" />
                                                        <geom quat="0 0 0 1" type="mesh" contype="0" conaffinity="0" group="1" mesh="half_round_tip" />
                                                        <geom size="0.004 0.004 0.0185" pos="0 -0.0045 -0.015" quat="0 0 0 1" type="box" />
                                                    </body>
                                                </body>
                                                <body name="r_gripper_r_finger" pos="0 0.0015 0.02">
                                                    <inertial pos="0 0 0" mass="0.02" diaginertia="0.01 0.01 0.01" />
                                                    <joint name="r_gripper_r_finger_joint" pos="0 0 0" axis="0 1 0" type="slide" limited="true" range="-0.020833 0" />
                                                    <geom type="mesh" contype="0" conaffinity="0" group="1" mesh="standard_narrow" />
                                                    <geom size="0.005 0.00675 0.0375" pos="0 -0.01725 0.04" type="box" />
                                                    <geom size="0.005 0.025 0.0085" pos="0.005 0.003 0.0083" type="box" />
                                                    <body name="r_gripper_r_finger_tip" pos="0 -0.01725 0.075">
                                                        <inertial pos="0 0 0" mass="0.01" diaginertia="0.01 0.01 0.01" />
                                                        <geom type="mesh" contype="0" conaffinity="0" group="1" mesh="half_round_tip" />
                                                        <geom size="0.004 0.004 0.0185" pos="0 0.0045 -0.015" type="box" />
                                                    </body>
                                                </body>
                                            </body>
                                        </body>
                                    </body>
                                </body>
                            </body>
                        </body>
                    </body>
                </body>
            </body>
        </body>
    </worldbody>
</mujoco>
