<mujoco model="base">
    <asset>
        <mesh name="electric_gripper_base" file="meshes/two_finger_gripper/electric_gripper_base.STL" />
        <mesh name="standard_narrow" file="meshes/two_finger_gripper/standard_narrow.STL" />
        <mesh name="half_round_tip" file="meshes/two_finger_gripper/half_round_tip.STL" />
    </asset>

    <actuator>
        <position ctrllimited="true" ctrlrange="-0.1 0.050833" joint="r_gripper_r_finger_joint" kp="10000" name="gripper_r_gripper_r_finger_joint" forcelimited="true" forcerange="-20 20"/>
        <position ctrllimited="true" ctrlrange="-0.050833 0.1" joint="r_gripper_l_finger_joint" kp="10000" name="gripper_r_gripper_l_finger_joint" forcelimited="true" forcerange="-20 20"/>
    </actuator>
    
    <worldbody>
        <inertial pos="1e-08 1e-08 1e-08" quat="0.820473 0.339851 -0.17592 0.424708" mass="1e-08" diaginertia="1e-08 1e-08 1e-08" />
        <geom size="1e-08 5e-09" type="cylinder" />
        <body name="right_gripper_base" pos="0 0 0.025">
            <inertial pos="0 0 0" quat="-0.5 0.5 0.5 0.5" mass="0.3" diaginertia="3e-08 2e-08 2e-08" />
            <geom quat="0 0 0.707107 0.707107" type="mesh" contype="0" conaffinity="0" group="1" mesh="electric_gripper_base" />
            <geom size="0.029 0.05" quat="0 0 0.707107 0.707107" type="cylinder" />
            <body name="right_gripper" pos="0 0 0.095">
                <inertial pos="0 0 0" mass="0.0001" diaginertia="0 0 0" />
            </body>
            <body name="r_gripper_l_finger" pos="0 0.05 0.02">
                <inertial pos="0 0 0" quat="0 0 0 -1" mass="0.02" diaginertia="0.01 0.01 0.01" />
                <joint name="r_gripper_l_finger_joint" pos="0 0 0" axis="0 1 0" type="slide" limited="true" range="-0.1 0.050833" damping="0.7"/>
                <geom quat="0 0 0 -1" type="mesh" contype="0" conaffinity="0" group="1" mesh="standard_narrow" />
                <geom size="0.005 0.00675 0.0375" pos="0 0.01725 0.04" quat="0 0 0 -1" type="box" />
                <geom size="0.005 0.025 0.0085" pos="-0.005 -0.003 0.0083" quat="0 0 0 -1" type="box" />
                <body name="r_gripper_l_finger_tip" pos="0 0.01725 0.075">
                    <inertial pos="0 0 0" quat="0 0 0 1" mass="0.01" diaginertia="0.01 0.01 0.01" />
                    <geom quat="0 0 0 1" type="mesh" contype="0" conaffinity="0" group="1" mesh="half_round_tip" />
                    <geom size="0.004 0.004 0.0185" pos="0 -0.0045 -0.015" quat="0 0 0 1" type="box" />
                </body>
            </body>
            <body name="r_gripper_r_finger" pos="0 -0.05 0.02">
                <inertial pos="0 0 0" mass="0.02" diaginertia="0.01 0.01 0.01" />
                <joint name="r_gripper_r_finger_joint" pos="0 0 0" axis="0 1 0" type="slide" limited="true" range="-0.050833 0.1" damping="0.7"/>
                <geom type="mesh" contype="0" conaffinity="0" group="1" mesh="standard_narrow" />
                <geom size="0.005 0.00675 0.0375" pos="0 -0.01725 0.04" type="box" />
                <geom size="0.005 0.025 0.0085" pos="0.005 0.003 0.0083" type="box" />
                <body name="r_gripper_r_finger_tip" pos="0 -0.01725 0.075">
                    <inertial pos="0 0 0" mass="0.01" diaginertia="0.01 0.01 0.01" />
                    <geom type="mesh" contype="0" conaffinity="0" group="1" mesh="half_round_tip" />
                    <geom size="0.004 0.004 0.0185" pos="0 0.0045 -0.015" type="box" />
                </body>
            </body>
        </body>
    </worldbody>
</mujoco>